<?xml version="1.0" encoding="UTF-8"?>
<testng-results skipped="1" failed="1" total="4" passed="2">
  <reporter-output>
  </reporter-output>
  <suite name="Default suite" duration-ms="26482" started-at="2017-02-07T12:37:32Z" finished-at="2017-02-07T12:37:58Z">
    <groups>
    </groups>
    <test name="Default test" duration-ms="26482" started-at="2017-02-07T12:37:32Z" finished-at="2017-02-07T12:37:58Z">
      <class name="test.poc.login.TestCases">
        <test-method status="PASS" signature="init()[pri:0, instance:test.poc.login.TestCases@c038203]" name="init" is-config="true" duration-ms="3616" started-at="2017-02-07T18:07:32Z" finished-at="2017-02-07T18:07:36Z">
          <reporter-output>
          </reporter-output>
        </test-method> <!-- init -->
        <test-method status="PASS" signature="logInTest()[pri:0, instance:test.poc.login.TestCases@c038203]" name="logInTest" duration-ms="22829" started-at="2017-02-07T18:07:36Z" finished-at="2017-02-07T18:07:58Z">
          <reporter-output>
          </reporter-output>
        </test-method> <!-- logInTest -->
        <test-method status="PASS" signature="passTest()[pri:1, instance:test.poc.login.TestCases@c038203]" name="passTest" duration-ms="2" started-at="2017-02-07T18:07:58Z" finished-at="2017-02-07T18:07:58Z">
          <reporter-output>
          </reporter-output>
        </test-method> <!-- passTest -->
        <test-method status="FAIL" signature="failTest()[pri:2, instance:test.poc.login.TestCases@c038203]" name="failTest" duration-ms="3" started-at="2017-02-07T18:07:58Z" finished-at="2017-02-07T18:07:58Z">
          <exception class="java.lang.AssertionError">
            <message>
              <![CDATA[expected [false] but found [true]]]>
            </message>
            <full-stacktrace>
              <![CDATA[java.lang.AssertionError: expected [false] but found [true]
	at org.testng.Assert.fail(Assert.java:94)
	at org.testng.Assert.failNotEquals(Assert.java:496)
	at org.testng.Assert.assertFalse(Assert.java:63)
	at org.testng.Assert.assertFalse(Assert.java:73)
	at test.poc.login.TestCases.failTest(TestCases.java:56)
	at sun.reflect.NativeMethodAccessorImpl.invoke0(Native Method)
	at sun.reflect.NativeMethodAccessorImpl.invoke(Unknown Source)
	at sun.reflect.DelegatingMethodAccessorImpl.invoke(Unknown Source)
	at java.lang.reflect.Method.invoke(Unknown Source)
	at org.testng.internal.MethodInvocationHelper.invokeMethod(MethodInvocationHelper.java:85)
	at org.testng.internal.Invoker.invokeMethod(Invoker.java:639)
	at org.testng.internal.Invoker.invokeTestMethod(Invoker.java:816)
	at org.testng.internal.Invoker.invokeTestMethods(Invoker.java:1124)
	at org.testng.internal.TestMethodWorker.invokeTestMethods(TestMethodWorker.java:125)
	at org.testng.internal.TestMethodWorker.run(TestMethodWorker.java:108)
	at org.testng.TestRunner.privateRun(TestRunner.java:774)
	at org.testng.TestRunner.run(TestRunner.java:624)
	at org.testng.SuiteRunner.runTest(SuiteRunner.java:359)
	at org.testng.SuiteRunner.runSequentially(SuiteRunner.java:354)
	at org.testng.SuiteRunner.privateRun(SuiteRunner.java:312)
	at org.testng.SuiteRunner.run(SuiteRunner.java:261)
	at org.testng.SuiteRunnerWorker.runSuite(SuiteRunnerWorker.java:52)
	at org.testng.SuiteRunnerWorker.run(SuiteRunnerWorker.java:86)
	at org.testng.TestNG.runSuitesSequentially(TestNG.java:1215)
	at org.testng.TestNG.runSuitesLocally(TestNG.java:1140)
	at org.testng.TestNG.run(TestNG.java:1048)
	at org.testng.remote.AbstractRemoteTestNG.run(AbstractRemoteTestNG.java:126)
	at org.testng.remote.RemoteTestNG.initAndRun(RemoteTestNG.java:137)
	at org.testng.remote.RemoteTestNG.main(RemoteTestNG.java:58)
]]>
            </full-stacktrace>
          </exception> <!-- java.lang.AssertionError -->
          <reporter-output>
          </reporter-output>
        </test-method> <!-- failTest -->
        <test-method status="SKIP" signature="skippedTest()[pri:3, instance:test.poc.login.TestCases@c038203]" name="skippedTest" duration-ms="0" started-at="2017-02-07T18:07:58Z" depends-on-methods="test.poc.login.TestCases.failTest" finished-at="2017-02-07T18:07:58Z">
          <exception class="java.lang.Throwable">
            <message>
              <![CDATA[Method TestCases.skippedTest()[pri:3, instance:test.poc.login.TestCases@c038203] depends on not successfully finished methods]]>
            </message>
            <full-stacktrace>
              <![CDATA[java.lang.Throwable: Method TestCases.skippedTest()[pri:3, instance:test.poc.login.TestCases@c038203] depends on not successfully finished methods
	at org.testng.internal.Invoker.invokeTestMethods(Invoker.java:1033)
	at org.testng.internal.TestMethodWorker.invokeTestMethods(TestMethodWorker.java:125)
	at org.testng.internal.TestMethodWorker.run(TestMethodWorker.java:108)
	at org.testng.TestRunner.privateRun(TestRunner.java:774)
	at org.testng.TestRunner.run(TestRunner.java:624)
	at org.testng.SuiteRunner.runTest(SuiteRunner.java:359)
	at org.testng.SuiteRunner.runSequentially(SuiteRunner.java:354)
	at org.testng.SuiteRunner.privateRun(SuiteRunner.java:312)
	at org.testng.SuiteRunner.run(SuiteRunner.java:261)
	at org.testng.SuiteRunnerWorker.runSuite(SuiteRunnerWorker.java:52)
	at org.testng.SuiteRunnerWorker.run(SuiteRunnerWorker.java:86)
	at org.testng.TestNG.runSuitesSequentially(TestNG.java:1215)
	at org.testng.TestNG.runSuitesLocally(TestNG.java:1140)
	at org.testng.TestNG.run(TestNG.java:1048)
	at org.testng.remote.AbstractRemoteTestNG.run(AbstractRemoteTestNG.java:126)
	at org.testng.remote.RemoteTestNG.initAndRun(RemoteTestNG.java:137)
	at org.testng.remote.RemoteTestNG.main(RemoteTestNG.java:58)
]]>
            </full-stacktrace>
          </exception> <!-- java.lang.Throwable -->
          <reporter-output>
          </reporter-output>
        </test-method> <!-- skippedTest -->
      </class> <!-- test.poc.login.TestCases -->
    </test> <!-- Default test -->
  </suite> <!-- Default suite -->
</testng-results>
